[2024-07-31T19:04:05.842+0000] {local_task_job_runner.py:120} INFO - ::group::Pre task execution logs
[2024-07-31T19:04:05.853+0000] {taskinstance.py:2076} INFO - Dependencies all met for dep_context=non-requeueable deps ti=<TaskInstance: weather-app.is_weather_api_ready scheduled__2024-07-30T00:00:00+00:00 [queued]>
[2024-07-31T19:04:05.859+0000] {taskinstance.py:2076} INFO - Dependencies all met for dep_context=requeueable deps ti=<TaskInstance: weather-app.is_weather_api_ready scheduled__2024-07-30T00:00:00+00:00 [queued]>
[2024-07-31T19:04:05.859+0000] {taskinstance.py:2306} INFO - Starting attempt 1 of 3
[2024-07-31T19:04:05.875+0000] {taskinstance.py:2330} INFO - Executing <Task(HttpSensor): is_weather_api_ready> on 2024-07-30 00:00:00+00:00
[2024-07-31T19:04:05.879+0000] {standard_task_runner.py:64} INFO - Started process 5485 to run task
[2024-07-31T19:04:05.882+0000] {standard_task_runner.py:90} INFO - Running: ['airflow', 'tasks', 'run', 'weather-app', 'is_weather_api_ready', 'scheduled__2024-07-30T00:00:00+00:00', '--job-id', '3', '--raw', '--subdir', 'DAGS_FOLDER/weather_dags.py', '--cfg-path', '/tmp/tmp1ifp2xyc']
[2024-07-31T19:04:05.883+0000] {standard_task_runner.py:91} INFO - Job 3: Subtask is_weather_api_ready
[2024-07-31T19:04:05.921+0000] {task_command.py:426} INFO - Running <TaskInstance: weather-app.is_weather_api_ready scheduled__2024-07-30T00:00:00+00:00 [running]> on host ip-172-31-15-224.ap-southeast-2.compute.internal
[2024-07-31T19:04:05.983+0000] {taskinstance.py:2648} INFO - Exporting env vars: AIRFLOW_CTX_DAG_OWNER='airflow' AIRFLOW_CTX_DAG_ID='weather-app' AIRFLOW_CTX_TASK_ID='is_weather_api_ready' AIRFLOW_CTX_EXECUTION_DATE='2024-07-30T00:00:00+00:00' AIRFLOW_CTX_TRY_NUMBER='1' AIRFLOW_CTX_DAG_RUN_ID='scheduled__2024-07-30T00:00:00+00:00'
[2024-07-31T19:04:05.985+0000] {taskinstance.py:430} INFO - ::endgroup::
[2024-07-31T19:04:05.985+0000] {baseoperator.py:400} WARNING - HttpSensor.execute cannot be called outside TaskInstance!
[2024-07-31T19:04:05.985+0000] {http.py:137} INFO - Poking: https://api.openweathermap.org/data/2.5/weather?q=Portland&appid=e1c2b88664f3211ebc372dda792b7c58
[2024-07-31T19:04:05.989+0000] {base.py:84} INFO - Using connection ID 'weatherapp_api' for task execution.
[2024-07-31T19:04:06.282+0000] {http.py:200} ERROR - HTTP error: Not Found
[2024-07-31T19:04:06.283+0000] {http.py:201} ERROR - <html>
<head><title>404 Not Found</title></head>
<body>
<center><h1>404 Not Found</h1></center>
<hr><center>openresty</center>
</body>
</html>

[2024-07-31T19:05:06.284+0000] {http.py:137} INFO - Poking: https://api.openweathermap.org/data/2.5/weather?q=Portland&appid=e1c2b88664f3211ebc372dda792b7c58
[2024-07-31T19:05:06.286+0000] {base.py:84} INFO - Using connection ID 'weatherapp_api' for task execution.
[2024-07-31T19:05:06.576+0000] {http.py:200} ERROR - HTTP error: Not Found
[2024-07-31T19:05:06.576+0000] {http.py:201} ERROR - <html>
<head><title>404 Not Found</title></head>
<body>
<center><h1>404 Not Found</h1></center>
<hr><center>openresty</center>
</body>
</html>

[2024-07-31T19:06:06.577+0000] {http.py:137} INFO - Poking: https://api.openweathermap.org/data/2.5/weather?q=Portland&appid=e1c2b88664f3211ebc372dda792b7c58
[2024-07-31T19:06:06.580+0000] {base.py:84} INFO - Using connection ID 'weatherapp_api' for task execution.
[2024-07-31T19:06:06.868+0000] {http.py:200} ERROR - HTTP error: Not Found
[2024-07-31T19:06:06.868+0000] {http.py:201} ERROR - <html>
<head><title>404 Not Found</title></head>
<body>
<center><h1>404 Not Found</h1></center>
<hr><center>openresty</center>
</body>
</html>

[2024-07-31T19:07:06.869+0000] {http.py:137} INFO - Poking: https://api.openweathermap.org/data/2.5/weather?q=Portland&appid=e1c2b88664f3211ebc372dda792b7c58
[2024-07-31T19:07:06.871+0000] {base.py:84} INFO - Using connection ID 'weatherapp_api' for task execution.
[2024-07-31T19:07:07.163+0000] {http.py:200} ERROR - HTTP error: Not Found
[2024-07-31T19:07:07.164+0000] {http.py:201} ERROR - <html>
<head><title>404 Not Found</title></head>
<body>
<center><h1>404 Not Found</h1></center>
<hr><center>openresty</center>
</body>
</html>

[2024-07-31T19:08:07.164+0000] {http.py:137} INFO - Poking: https://api.openweathermap.org/data/2.5/weather?q=Portland&appid=e1c2b88664f3211ebc372dda792b7c58
[2024-07-31T19:08:07.167+0000] {base.py:84} INFO - Using connection ID 'weatherapp_api' for task execution.
[2024-07-31T19:08:07.455+0000] {http.py:200} ERROR - HTTP error: Not Found
[2024-07-31T19:08:07.455+0000] {http.py:201} ERROR - <html>
<head><title>404 Not Found</title></head>
<body>
<center><h1>404 Not Found</h1></center>
<hr><center>openresty</center>
</body>
</html>

[2024-07-31T19:09:07.455+0000] {http.py:137} INFO - Poking: https://api.openweathermap.org/data/2.5/weather?q=Portland&appid=e1c2b88664f3211ebc372dda792b7c58
[2024-07-31T19:09:07.458+0000] {base.py:84} INFO - Using connection ID 'weatherapp_api' for task execution.
[2024-07-31T19:09:07.751+0000] {http.py:200} ERROR - HTTP error: Not Found
[2024-07-31T19:09:07.751+0000] {http.py:201} ERROR - <html>
<head><title>404 Not Found</title></head>
<body>
<center><h1>404 Not Found</h1></center>
<hr><center>openresty</center>
</body>
</html>

[2024-07-31T19:10:07.751+0000] {http.py:137} INFO - Poking: https://api.openweathermap.org/data/2.5/weather?q=Portland&appid=e1c2b88664f3211ebc372dda792b7c58
[2024-07-31T19:10:07.754+0000] {base.py:84} INFO - Using connection ID 'weatherapp_api' for task execution.
[2024-07-31T19:10:08.050+0000] {http.py:200} ERROR - HTTP error: Not Found
[2024-07-31T19:10:08.051+0000] {http.py:201} ERROR - <html>
<head><title>404 Not Found</title></head>
<body>
<center><h1>404 Not Found</h1></center>
<hr><center>openresty</center>
</body>
</html>

[2024-07-31T19:11:08.051+0000] {http.py:137} INFO - Poking: https://api.openweathermap.org/data/2.5/weather?q=Portland&appid=e1c2b88664f3211ebc372dda792b7c58
[2024-07-31T19:11:08.054+0000] {base.py:84} INFO - Using connection ID 'weatherapp_api' for task execution.
[2024-07-31T19:11:08.342+0000] {http.py:200} ERROR - HTTP error: Not Found
[2024-07-31T19:11:08.342+0000] {http.py:201} ERROR - <html>
<head><title>404 Not Found</title></head>
<body>
<center><h1>404 Not Found</h1></center>
<hr><center>openresty</center>
</body>
</html>

[2024-07-31T19:12:08.342+0000] {http.py:137} INFO - Poking: https://api.openweathermap.org/data/2.5/weather?q=Portland&appid=e1c2b88664f3211ebc372dda792b7c58
[2024-07-31T19:12:08.345+0000] {base.py:84} INFO - Using connection ID 'weatherapp_api' for task execution.
[2024-07-31T19:12:08.636+0000] {http.py:200} ERROR - HTTP error: Not Found
[2024-07-31T19:12:08.636+0000] {http.py:201} ERROR - <html>
<head><title>404 Not Found</title></head>
<body>
<center><h1>404 Not Found</h1></center>
<hr><center>openresty</center>
</body>
</html>

[2024-07-31T19:13:08.637+0000] {http.py:137} INFO - Poking: https://api.openweathermap.org/data/2.5/weather?q=Portland&appid=e1c2b88664f3211ebc372dda792b7c58
[2024-07-31T19:13:08.639+0000] {base.py:84} INFO - Using connection ID 'weatherapp_api' for task execution.
[2024-07-31T19:13:08.928+0000] {http.py:200} ERROR - HTTP error: Not Found
[2024-07-31T19:13:08.928+0000] {http.py:201} ERROR - <html>
<head><title>404 Not Found</title></head>
<body>
<center><h1>404 Not Found</h1></center>
<hr><center>openresty</center>
</body>
</html>

[2024-07-31T19:14:08.929+0000] {http.py:137} INFO - Poking: https://api.openweathermap.org/data/2.5/weather?q=Portland&appid=e1c2b88664f3211ebc372dda792b7c58
[2024-07-31T19:14:08.931+0000] {base.py:84} INFO - Using connection ID 'weatherapp_api' for task execution.
[2024-07-31T19:14:09.220+0000] {http.py:200} ERROR - HTTP error: Not Found
[2024-07-31T19:14:09.221+0000] {http.py:201} ERROR - <html>
<head><title>404 Not Found</title></head>
<body>
<center><h1>404 Not Found</h1></center>
<hr><center>openresty</center>
</body>
</html>

[2024-07-31T19:15:09.221+0000] {http.py:137} INFO - Poking: https://api.openweathermap.org/data/2.5/weather?q=Portland&appid=e1c2b88664f3211ebc372dda792b7c58
[2024-07-31T19:15:09.224+0000] {base.py:84} INFO - Using connection ID 'weatherapp_api' for task execution.
[2024-07-31T19:15:09.512+0000] {http.py:200} ERROR - HTTP error: Not Found
[2024-07-31T19:15:09.512+0000] {http.py:201} ERROR - <html>
<head><title>404 Not Found</title></head>
<body>
<center><h1>404 Not Found</h1></center>
<hr><center>openresty</center>
</body>
</html>

[2024-07-31T19:16:09.512+0000] {http.py:137} INFO - Poking: https://api.openweathermap.org/data/2.5/weather?q=Portland&appid=e1c2b88664f3211ebc372dda792b7c58
[2024-07-31T19:16:09.515+0000] {base.py:84} INFO - Using connection ID 'weatherapp_api' for task execution.
[2024-07-31T19:16:09.805+0000] {http.py:200} ERROR - HTTP error: Not Found
[2024-07-31T19:16:09.805+0000] {http.py:201} ERROR - <html>
<head><title>404 Not Found</title></head>
<body>
<center><h1>404 Not Found</h1></center>
<hr><center>openresty</center>
</body>
</html>

[2024-07-31T19:17:09.806+0000] {http.py:137} INFO - Poking: https://api.openweathermap.org/data/2.5/weather?q=Portland&appid=e1c2b88664f3211ebc372dda792b7c58
[2024-07-31T19:17:09.809+0000] {base.py:84} INFO - Using connection ID 'weatherapp_api' for task execution.
[2024-07-31T19:17:10.229+0000] {http.py:200} ERROR - HTTP error: Not Found
[2024-07-31T19:17:10.229+0000] {http.py:201} ERROR - <html>
<head><title>404 Not Found</title></head>
<body>
<center><h1>404 Not Found</h1></center>
<hr><center>openresty</center>
</body>
</html>

[2024-07-31T19:18:07.545+0000] {local_task_job_runner.py:222} INFO - ::endgroup::
[2024-07-31T19:18:07.551+0000] {process_utils.py:132} INFO - Sending 15 to group 5485. PIDs of all processes in the group: [5485]
[2024-07-31T19:18:07.551+0000] {process_utils.py:87} INFO - Sending the signal 15 to group 5485
[2024-07-31T19:18:07.551+0000] {taskinstance.py:2611} ERROR - Received SIGTERM. Terminating subprocesses.
[2024-07-31T19:18:07.552+0000] {taskinstance.py:441} INFO - ::group::Post task execution logs
[2024-07-31T19:18:07.564+0000] {taskinstance.py:2905} ERROR - Task failed with exception
Traceback (most recent call last):
  File "/home/ubuntu/airflow-venv/lib/python3.12/site-packages/airflow/models/taskinstance.py", line 465, in _execute_task
    result = _execute_callable(context=context, **execute_callable_kwargs)
             ^^^^^^^^^^^^^^^^^^^^^^^^^^^^^^^^^^^^^^^^^^^^^^^^^^^^^^^^^^^^^
  File "/home/ubuntu/airflow-venv/lib/python3.12/site-packages/airflow/models/taskinstance.py", line 432, in _execute_callable
    return execute_callable(context=context, **execute_callable_kwargs)
           ^^^^^^^^^^^^^^^^^^^^^^^^^^^^^^^^^^^^^^^^^^^^^^^^^^^^^^^^^^^^
  File "/home/ubuntu/airflow-venv/lib/python3.12/site-packages/airflow/models/baseoperator.py", line 401, in wrapper
    return func(self, *args, **kwargs)
           ^^^^^^^^^^^^^^^^^^^^^^^^^^^
  File "/home/ubuntu/airflow-venv/lib/python3.12/site-packages/airflow/providers/http/sensors/http.py", line 164, in execute
    super().execute(context=context)
  File "/home/ubuntu/airflow-venv/lib/python3.12/site-packages/airflow/models/baseoperator.py", line 401, in wrapper
    return func(self, *args, **kwargs)
           ^^^^^^^^^^^^^^^^^^^^^^^^^^^
  File "/home/ubuntu/airflow-venv/lib/python3.12/site-packages/airflow/sensors/base.py", line 292, in execute
    time.sleep(self._get_next_poke_interval(started_at, run_duration, poke_count))
  File "/home/ubuntu/airflow-venv/lib/python3.12/site-packages/airflow/models/taskinstance.py", line 2613, in signal_handler
    raise AirflowTaskTerminated("Task received SIGTERM signal")
airflow.exceptions.AirflowTaskTerminated: Task received SIGTERM signal
[2024-07-31T19:18:07.568+0000] {taskinstance.py:1206} INFO - Marking task as UP_FOR_RETRY. dag_id=weather-app, task_id=is_weather_api_ready, run_id=scheduled__2024-07-30T00:00:00+00:00, execution_date=20240730T000000, start_date=20240731T190405, end_date=20240731T191807
[2024-07-31T19:18:07.605+0000] {process_utils.py:80} INFO - Process psutil.Process(pid=5485, status='terminated', exitcode=2, started='19:04:04') (5485) terminated with exit code 2
